{
    "DWF": {
        "references": [
            "https://bugzilla.redhat.com/show_bug.cgi?id=CVE-2021-3533",
            "https://bugzilla.redhat.com/show_bug.cgi?id=1956477",
            "https://www.suse.com/security/cve/CVE-2021-3533/",
            "https://ubuntu.com/security/CVE-2021-3533",
            "https://security.archlinux.org/CVE-2021-3533",
            "https://www.whitesourcesoftware.com/vulnerability-database/CVE-2021-3533"
        ]
    },
    "MITRE": {
        "CVE_data_meta": {
            "ASSIGNER": "secalert@redhat.com",
            "ID": "CVE-2021-3533",
            "STATE": "PUBLIC"
        },
        "affects": {
            "vendor": {
                "vendor_data": [
                    {
                        "product": {
                            "product_data": [
                                {
                                    "product_name": "ansible",
                                    "version": {
                                        "version_data": [
                                            {
                                                "version_value": "Ansible Tower 3.7 and Ansible Automation Platform 1.2"
                                            }
                                        ]
                                    }
                                }
                            ]
                        },
                        "vendor_name": "n/a"
                    }
                ]
            }
        },
        "data_format": "MITRE",
        "data_type": "CVE",
        "data_version": "4.0",
        "description": {
            "description_data": [
                {
                    "lang": "eng",
                    "value": "A flaw was found in Ansible if an ansible user sets ANSIBLE_ASYNC_DIR to a subdirectory of a world writable directory. When this occurs, there is a race condition on the managed machine. A malicious, non-privileged account on the remote machine can exploit the race condition to access the async result data. This flaw affects Ansible Tower 3.7 and Ansible Automation Platform 1.2."
                }
            ]
        },
        "problemtype": {
            "problemtype_data": [
                {
                    "description": [
                        {
                            "lang": "eng",
                            "value": "CWE-367"
                        }
                    ]
                }
            ]
        },
        "references": {
            "reference_data": [
                {
                    "name": "https://bugzilla.redhat.com/show_bug.cgi?id=1956477",
                    "refsource": "MISC",
                    "url": "https://bugzilla.redhat.com/show_bug.cgi?id=1956477"
                }
            ]
        }
    },
    "NVD": {
        "configurations": {
            "CVE_data_version": "4.0",
            "nodes": []
        },
        "cve": {
            "CVE_data_meta": {
                "ASSIGNER": "secalert@redhat.com",
                "ID": "CVE-2021-3533"
            },
            "data_format": "MITRE",
            "data_type": "CVE",
            "data_version": "4.0",
            "description": {
                "description_data": [
                    {
                        "lang": "en",
                        "value": "A flaw was found in Ansible if an ansible user sets ANSIBLE_ASYNC_DIR to a subdirectory of a world writable directory. When this occurs, there is a race condition on the managed machine. A malicious, non-privileged account on the remote machine can exploit the race condition to access the async result data. This flaw affects Ansible Tower 3.7 and Ansible Automation Platform 1.2."
                    }
                ]
            },
            "problemtype": {
                "problemtype_data": [
                    {
                        "description": []
                    }
                ]
            },
            "references": {
                "reference_data": [
                    {
                        "name": "https://bugzilla.redhat.com/show_bug.cgi?id=1956477",
                        "refsource": "MISC",
                        "tags": [],
                        "url": "https://bugzilla.redhat.com/show_bug.cgi?id=1956477"
                    }
                ]
            }
        },
        "impact": {},
        "lastModifiedDate": "2021-06-09T12:38Z",
        "publishedDate": "2021-06-09T12:15Z"
    }
}